# How do I troubleshoot a Python TensorFlow error?
// plain

Troubleshooting errors in Python TensorFlow can be a complex process. To start, it is important to identify the source of the error. This can be done by examining the traceback provided by the error message. Once the source of the error has been identified, it is important to analyze the code and determine what is causing the error.

Below is an example of a Python TensorFlow error and traceback:

```
ValueError: Input 0 of layer sequential_1 is incompatible with the layer: expected axis -1 of input shape to have value 3 but received input with shape [None, 1]

Traceback (most recent call last):
  File "example.py", line 12, in <module>
    model.fit(x_train, y_train)
  File "C:\Users\user\AppData\Local\Programs\Python\Python37\lib\site-packages\tensorflow\python\keras\engine\training.py", line 66, in _method_wrapper
    return method(self, *args, **kwargs)
  File "C:\Users\user\AppData\Local\Programs\Python\Python37\lib\site-packages\tensorflow\python\keras\engine\training.py", line 848, in fit
    tmp_logs = train_function(iterator)
  File "C:\Users\user\AppData\Local\Programs\Python\Python37\lib\site-packages\tensorflow\python\eager\def_function.py", line 580, in __call__
    result = self._call(*args, **kwds)
  File "C:\Users\user\AppData\Local\Programs\Python\Python37\lib\site-packages\tensorflow\python\eager\def_function.py", line 638, in _call
    self._initialize(args, kwds, add_initializers_to=initializers)
  File "C:\Users\user\AppData\Local\Programs\Python\Python37\lib\site-packages\tensorflow\python\eager\def_function.py", line 494, in _initialize
    *args, **kwds))
  File "C:\Users\user\AppData\Local\Programs\Python\Python37\lib\site-packages\tensorflow\python\eager\function.py", line 2389, in _get_concrete_function_internal_garbage_collected
    graph_function, _, _ = self._maybe_define_function(args, kwargs)
  File "C:\Users\user\AppData\Local\Programs\Python\Python37\lib\site-packages\tensorflow\python\eager\function.py", line 2703, in _maybe_define_function
    graph_function = self._create_graph_function(args, kwargs)
  File "C:\Users\user\AppData\Local\Programs\Python\Python37\lib\site-packages\tensorflow\python\eager\function.py", line 2593, in _create_graph_function
    capture_by_value=self._capture_by_value),
  File "C:\Users\user\AppData\Local\Programs\Python\Python37\lib\site-packages\tensorflow\python\framework\func_graph.py", line 978, in func_graph_from_py_func
    func_outputs = python_func(*func_args, **func_kwargs)
  File "C:\Users\user\AppData\Local\Programs\Python\Python37\lib\site-packages\tensorflow\python\eager\def_function.py", line 441, in wrapped_fn
    return weak_wrapped_fn().__wrapped__(*args, **kwds)
  File "C:\Users\user\AppData\Local\Programs\Python\Python37\lib\site-packages\tensorflow\python\framework\func_graph.py", line 969, in wrapper
    raise e.ag_error_metadata.to_exception(e)
ValueError: in user code:

    example.py:12 model.fit  *
        model.fit(x_train, y_train)
    C:\Users\user\AppData\Local\Programs\Python\Python37\lib\site-packages\tensorflow\python\keras\engine\training.py:806 fit  **
        batch_size=batch_size):
    C:\Users\user\AppData\Local\Programs\Python\Python37\lib\site-packages\tensorflow\python\keras\engine\training.py:2419 _standardize_user_data
        exception_prefix='input')
    C:\Users\user\AppData\Local\Programs\Python\Python37\lib\site-packages\tensorflow\python\keras\engine\training_utils.py:586 standardize_input_data
        'with shape ' + str(data_shape))

    ValueError: Input 0 of layer sequential_1 is incompatible with the layer: expected axis -1 of input shape to have value 3 but received input with shape [None, 1]
```

The error message states that the input shape of layer 0 of the sequential_1 layer is incompatible with the expected shape. This indicates that the input data is not the correct shape for the model. To troubleshoot this issue, it is necessary to examine the code and check the shape of the input data.

For example, if the input data is a NumPy array, the shape can be checked using the `shape` attribute of the array:

```
print(x_train.shape)
```

## Output example


```
(1000, 3)
```

In this example, the shape of the input data is `(1000, 3)`, which is the expected shape for the model.

To troubleshoot Python TensorFlow errors, it is important to identify the source of the error, analyze the code, and check the shape of the input data.

## Helpful links

- [TensorFlow Error Messages](https://www.tensorflow.org/guide/error_messages)
- [How to Check the Shape of a NumPy Array](https://www.geeksforgeeks.org/numpy-shape-function/)

onelinerhub: [How do I troubleshoot a Python TensorFlow error?](https://onelinerhub.com/python-tensorflow/how-do-i-troubleshoot-a-python-tensorflow-error)